Workbook

Sheet Historical Financials
A1: ASIAN PAINTS LIMITED — HISTORICAL FINANCIALS
A2: ₹ crore, except per-share data
A4: INCOME STATEMENT
A5: Particulars | B5: FY23 | C5: FY24 | D5: FY25 | E5: FY26
A6: Revenue from Sale of Products | B6: 34253.35 | C6: 35248.88 | D6: 33626.82 | E6: 35416.25
A7: Revenue from Sale of Services | B7: 114.48 | C7: 133.24 | D7: 170.54 | E7: 100.12
A8: Other Operating Revenue | B8: 120.76 | C8: 112.61 | D8: 108.26 | E8: 67.17
A9: Revenue from Operations | B9: =SUM(B6:B8) -> 34488.59 | C9: =SUM(C6:C8) -> 35494.73 | D9: =SUM(D6:D8) -> 33905.62 | E9: =SUM(E6:E8) -> 35583.54
A10: Other Income | B10: 386.48 | C10: 687.96 | D10: 572.61 | E10: 723.8
A11: Total Income | B11: =B9+B10 -> 34875.07 | C11: =C9+C10 -> 36182.69 | D11: =D9+D10 -> 34478.23 | E11: =E9+E10 -> 36307.34
A12: Cost of Materials Consumed | B12: 17330.58 | C12: 15868.21 | D12: 15793.92 | E12: 15384.05
A13: Purchases of Stock-in-Trade | B13: 4135.65 | C13: 3858.2 | D13: 3926.86 | E13: 4014.05
A14: Changes in Inventories | B14: -309.73 | C14: 363.8 | D14: -205 | E14: 603.68
A15: Employee Benefits Expense | B15: 2028.07 | C15: 2326.18 | D15: 2597.23 | E15: 2799.59
A16: Other Expenses | B16: 5044.18 | C16: 5493.36 | D16: 5786.4 | E16: 6086.25
A17: Total Expenses | B17: =SUM(B12:B16) -> 28228.75 | C17: =SUM(C12:C16) -> 27909.75 | D17: =SUM(D12:D16) -> 27899.41 | E17: =SUM(E12:E16) -> 28887.62
A18: EBITDA | B18: =B11-B17 -> 6646.32 | C18: =C11-C17 -> 8272.94 | D18: =D11-D17 -> 6578.82 | E18: =E11-E17 -> 7419.72
A19: Finance Costs | B19: 144.45 | C19: 205.17 | D19: 227.02 | E19: 195.41
A20: Depreciation & Amortisation | B20: 858.02 | C20: 853 | D20: 1026.34 | E20: 1228.85
A21: Profit Before Associates & Exceptional Items | B21: =B18-B19-B20 -> 5643.85 | C21: =C18-C19-C20 -> 7214.77 | D21: =D18-D19-D20 -> 5325.46 | E21: =E18-E19-E20 -> 5995.46
A22: Share of Profit in Associates | B22: 93.85 | C22: 133 | D22: 140.71 | E22: 165.59
A23: Profit Before Exceptional Items & Tax | B23: =B21+B22 -> 5737.7 | C23: =C21+C22 -> 7347.77 | D23: =D21+D22 -> 5466.17 | E23: =E21+E22 -> 6161.05
A24: Exceptional Items | B24: 48.87 | C24: 0 | D24: 363.1 | E24: 157.61
A25: Profit Before Tax | B25: =B23-B24 -> 5688.83 | C25: =C23-C24 -> 7347.77 | D25: =D23-D24 -> 5103.07 | E25: =E23-E24 -> 6003.44
A26: Total Tax Expense | B26: 1493.5 | C26: 1790.08 | D26: 1393.36 | E26: 1608.75
A27: Profit After Tax | B27: =B25-B26 -> 4195.33 | C27: =C25-C26 -> 5557.69 | D27: =D25-D26 -> 3709.71 | E27: =E25-E26 -> 4394.69
A28: PAT Attributable to Owners | B28: 4106.45 | C28: 5460.23 | D28: 3667.23 | E28: 4325.35
A29: Diluted EPS (₹) | B29: 42.82 | C29: 56.94 | D29: 38.25 | E29: 45.11
A31: BALANCE SHEET
A32: Particulars | B32: FY23 | C32: FY24 | D32: FY25 | E32: FY26
A33: Property, Plant & Equipment | B33: 4145.65 | C33: 4446.2 | D33: 6787.62 | E33: 7146.23
A34: Right-of-Use Assets | B34: 1208.92 | C34: 1856.27 | D34: 1843.72 | E34: 2018.77
A35: Capital Work-in-Progress | B35: 1019.59 | C35: 2698.37 | D35: 1254.49 | E35: 1848.67
A36: Goodwill | B36: 228.48 | C36: 419.19 | D36: 219.58 | E36: 219.08
A37: Other Intangible Assets | B37: 187.41 | C37: 424.96 | D37: 369.18 | E37: 256.2
A38: Investments in Associates | B38: 781.73 | C38: 583.13 | D38: 608 | E38: 656.09
A39: Non-Current Investments | B39: 782.98 | C39: 801.38 | D39: 871.79 | E39: 119.82
A40: Trade Receivables — Non-Current | B40: 2.17 | C40: 1.78 | D40: 8.71 | E40: 5.36
A41: Other Financial Assets — Non-Current | B41: 363.18 | C41: 606.51 | D41: 877.84 | E41: 1539.36
A42: Deferred Tax Assets | B42: 18.67 | C42: 23.32 | D42: 16.12 | E42: 15.74
...

Sheet Financial Ratios
A1: FINANCIAL RATIOS
A3: Particulars | B3: FY24 | C3: FY25 | D3: FY26
A4: Revenue Growth | B4: ='Historical Financials'!C9/'Historical Financials'!B9-1 -> 0.029173127 | C4: ='Historical Financials'!D9/'Historical Financials'!C9-1 -> -0.044770308 | D4: ='Historical Financials'!E9/'Historical Financials'!D9-1 -> 0.049487961
A5: EBITDA Margin | B5: ='Historical Financials'!C18/'Historical Financials'!C9 -> 0.23307516 | C5: ='Historical Financials'!D18/'Historical Financials'!D9 -> 0.19403332 | D5: ='Historical Financials'!E18/'Historical Financials'!E9 -> 0.20851551
A6: EBIT Margin | B6: =('Historical Financials'!C18-'Historical Financials'!C20)/'Historical Financials'!C9 -> 0.20904343 | C6: =('Historical Financials'!D18-'Historical Financials'!D20)/'Historical Financials'!D9 -> 0.16376282 | D6: =('Historical Financials'!E18-'Historical Financials'!E20)/'Historical Financials'!E9 -> 0.17398128
A7: Net Profit Margin | B7: ='Historical Financials'!C27/'Historical Financials'!C9 -> 0.15657789 | C7: ='Historical Financials'!D27/'Historical Financials'!D9 -> 0.10941283 | D7: ='Historical Financials'!E27/'Historical Financials'!E9 -> 0.12350345
A8: ROE | B8: ='Historical Financials'!C27/AVERAGE('Historical Financials'!B58,'Historical Financials'!C58) -> 0.30988328 | C8: ='Historical Financials'!D27/AVERAGE('Historical Financials'!C58,'Historical Financials'!D58) -> 0.18791558 | D8: ='Historical Financials'!E27/AVERAGE('Historical Financials'!D58,'Historical Financials'!E58) -> 0.20890274
A9: ROCE | B9: =7419.94/AVERAGE(17902.07,21423.13) -> 0.37736312 | C9: =5552.48/AVERAGE(21423.13,22230.14) -> 0.25439011 | D9: =6190.87/AVERAGE(22230.14,25397.46) -> 0.25996985
A10: Debt-to-Equity | B10: =('Historical Financials'!C59+'Historical Financials'!C66)/'Historical Financials'!C58 -> 0.056999498 | C10: =('Historical Financials'!D59+'Historical Financials'!D66)/'Historical Financials'!D58 -> 0.043060364 | D10: =('Historical Financials'!E59+'Historical Financials'!E66)/'Historical Financials'!E58 -> 0.10416816
A11: Current Ratio | B11: ='Historical Financials'!C53/'Historical Financials'!C74 -> 2.0629505 | C11: ='Historical Financials'!D53/'Historical Financials'!D74 -> 2.0871146 | D11: ='Historical Financials'!E53/'Historical Financials'!E74 -> 2.209103
A12: Asset Turnover | B12: ='Historical Financials'!C9/'Historical Financials'!C54 -> 1.186159 | C12: ='Historical Financials'!D9/'Historical Financials'!D54 -> 1.1163678 | D12: ='Historical Financials'!E9/'Historical Financials'!E54 -> 1.0303769
A13: Interest Coverage | B13: =('Historical Financials'!C18-'Historical Financials'!C20)/'Historical Financials'!C19 -> 36.164839 | C13: =('Historical Financials'!D18-'Historical Financials'!D20)/'Historical Financials'!D19 -> 24.458109 | D13: =('Historical Financials'!E18-'Historical Financials'!E20)/'Historical Financials'!E19 -> 31.681439

Sheet Assumptions
A1: ASSUMPTIONS
A3: Particulars | B3: FY27 | C3: FY28 | D3: FY29 | E3: FY30 | F3: FY31
A4: Revenue Growth | B4: 0.05 | C4: 0.05 | D4: 0.045 | E4: 0.04 | F4: 0.04
A5: EBITDA Margin | B5: 0.21 | C5: 0.215 | D5: 0.22 | E5: 0.22 | F5: 0.22
A6: D&A % Revenue | B6: 0.035 | C6: 0.035 | D6: 0.035 | E6: 0.035 | F6: 0.035
A7: Tax Rate | B7: 0.25 | C7: 0.25 | D7: 0.25 | E7: 0.25 | F7: 0.25
A8: Accounts Receivable % Revenue | B8: 0.05 | C8: 0.05 | D8: 0.05 | E8: 0.05 | F8: 0.05
A9: Inventory % Revenue | B9: 0.09 | C9: 0.09 | D9: 0.09 | E9: 0.09 | F9: 0.09
A10: Accounts Payable % Revenue | B10: 0.06 | C10: 0.06 | D10: 0.06 | E10: 0.06 | F10: 0.06
A11: Capex % Revenue | B11: 0.04 | C11: 0.04 | D11: 0.04 | E11: 0.04 | F11: 0.04
A14: DCF & WACC ASSUMPTIONS
A15: Particulars | B15: Assumption
A16: Risk-Free Rate | B16: 0.065
A17: Equity Risk Premium | B17: 0.06
A18: Beta | B18: 0.9
A19: Pre-Tax Cost of Debt | B19: 0.07
A20: Terminal Growth | B20: 0.05

Sheet Forecast
A1: FORECAST
A3: Particulars | B3: FY26A | C3: FY27E | D3: FY28E | E3: FY29E | F3: FY30E | G3: FY31E
A4: Revenue | B4: ='Historical Financials'!E9 -> 35583.54 | C4: =B4*(1+Assumptions!B4) -> 37362.717 | D4: =C4*(1+Assumptions!C4) -> 39230.853 | E4: =D4*(1+Assumptions!D4) -> 40996.241 | F4: =E4*(1+Assumptions!E4) -> 42636.091 | G4: =F4*(1+Assumptions!F4) -> 44341.535
A5: Revenue Growth | B5: ='Financial Ratios'!D4 -> 0.049487961 | C5: =Assumptions!B4 -> 0.05 | D5: =Assumptions!C4 -> 0.05 | E5: =Assumptions!D4 -> 0.045 | F5: =Assumptions!E4 -> 0.04 | G5: =Assumptions!F4 -> 0.04
A6: EBITDA | B6: ='Historical Financials'!E18 -> 7419.72 | C6: =C4*Assumptions!B5 -> 7846.1706 | D6: =D4*Assumptions!C5 -> 8434.6334 | E6: =E4*Assumptions!D5 -> 9019.1731 | F6: =F4*Assumptions!E5 -> 9379.94 | G6: =G4*Assumptions!F5 -> 9755.1376
A7: EBITDA Margin | B7: ='Financial Ratios'!D5 -> 0.20851551 | C7: =Assumptions!B5 -> 0.21 | D7: =Assumptions!C5 -> 0.215 | E7: =Assumptions!D5 -> 0.22 | F7: =Assumptions!E5 -> 0.22 | G7: =Assumptions!F5 -> 0.22
A8: D&A | B8: ='Historical Financials'!E20 -> 1228.85 | C8: =C4*Assumptions!B6 -> 1307.6951 | D8: =D4*Assumptions!C6 -> 1373.0799 | E8: =E4*Assumptions!D6 -> 1434.8684 | F8: =F4*Assumptions!E6 -> 1492.2632 | G8: =G4*Assumptions!F6 -> 1551.9537
A9: EBIT | B9: =B6-B8 -> 6190.87 | C9: =C6-C8 -> 6538.4755 | D9: =D6-D8 -> 7061.5535 | E9: =E6-E8 -> 7584.3046 | F9: =F6-F8 -> 7887.6768 | G9: =G6-G8 -> 8203.1839
A10: EBIT Margin | B10: =B9/B4 -> 0.17398128 | C10: =C9/C4 -> 0.175 | D10: =D9/D4 -> 0.18 | E10: =E9/E4 -> 0.185 | F10: =F9/F4 -> 0.185 | G10: =G9/G4 -> 0.185
A11: Tax | B11: ='Historical Financials'!E26 -> 1608.75 | C11: =C9*Assumptions!B7 -> 1634.6189 | D11: =D9*Assumptions!C7 -> 1765.3884 | E11: =E9*Assumptions!D7 -> 1896.0762 | F11: =F9*Assumptions!E7 -> 1971.9192 | G11: =G9*Assumptions!F7 -> 2050.796
A12: NOPAT | B12: =B9-B11 -> 4582.12 | C12: =C9-C11 -> 4903.8566 | D12: =D9-D11 -> 5296.1651 | E12: =E9-E11 -> 5688.2285 | F12: =F9-F11 -> 5915.7576 | G12: =G9-G11 -> 6152.3879
A15: Model note
A16: Forecast uses the assumptions sheet; DCF will use EBIT, NOPAT, Capex and working capital.

Sheet WACC
A1: WACC CALCULATION
A2: Particulars
A3: Value
A4: Risk-Free Rate | B4: =Assumptions!B16 -> 0.065
A5: Equity Risk Premium | B5: =Assumptions!B17 -> 0.06
A6: Beta | B6: =Assumptions!B18 -> 0.9
A7: Cost of Equity | B7: =B4+B6*B5 -> 0.119
A8: Pre-Tax Cost of Debt | B8: =Assumptions!B19 -> 0.07
A9: Tax Rate | B9: =Assumptions!B7 -> 0.25
A10: After-Tax Cost of Debt | B10: =B8*(1-B9) -> 0.0525
A11: Equity Value | B11: 230476 | D11: Asian Paints Ltd
A12: Debt Value | B12: ='Historical Financials'!E59+'Historical Financials'!E66 -> 2293.26
A13: Total Capital | B13: =B11+B12 -> 232769.26
A14: Equity Weight | B14: =B11/B13 -> 0.99014793
A15: Debt Weight | B15: =B12/B13 -> 0.0098520741
A16: WACC | B16: =B14*B7+B15*B10 -> 0.11834484

Sheet DCF Valuation
A1: DCF VALUATION
A3: Particulars | B3: FY26A | C3: FY27E | D3: FY28E | E3: FY29E | F3: FY30E | G3: FY31E
A4: EBIT | B4: =Forecast!B9 -> 6190.87 | C4: =Forecast!C9 -> 6538.4755 | D4: =Forecast!D9 -> 7061.5535 | E4: =Forecast!E9 -> 7584.3046 | F4: =Forecast!F9 -> 7887.6768 | G4: =Forecast!G9 -> 8203.1839
A5: Tax | B5: =Forecast!B11 -> 1608.75 | C5: =Forecast!C11 -> 1634.6189 | D5: =Forecast!D11 -> 1765.3884 | E5: =Forecast!E11 -> 1896.0762 | F5: =Forecast!F11 -> 1971.9192 | G5: =Forecast!G11 -> 2050.796
A6: NOPAT | B6: =Forecast!B12 -> 4582.12 | C6: =Forecast!C12 -> 4903.8566 | D6: =Forecast!D12 -> 5296.1651 | E6: =Forecast!E12 -> 5688.2285 | F6: =Forecast!F12 -> 5915.7576 | G6: =Forecast!G12 -> 6152.3879
A7: D&A | B7: =Forecast!B8 -> 1228.85 | C7: =Forecast!C8 -> 1307.6951 | D7: =Forecast!D8 -> 1373.0799 | E7: =Forecast!E8 -> 1434.8684 | F7: =Forecast!F8 -> 1492.2632 | G7: =Forecast!G8 -> 1551.9537
A8: Capex | B8: =1467.02 -> 1467.02 | C8: =Forecast!C4*Assumptions!B11 -> 1494.5087 | D8: =Forecast!D4*Assumptions!C11 -> 1569.2341 | E8: =Forecast!E4*Assumptions!D11 -> 1639.8496 | F8: =Forecast!F4*Assumptions!E11 -> 1705.4436 | G8: =Forecast!G4*Assumptions!F11 -> 1773.6614
A9: Accounts Receivable | B9: ='Historical Financials'!E48 -> 4461.8 | C9: =Forecast!C4*Assumptions!B8 -> 1868.1358 | D9: =Forecast!D4*Assumptions!C8 -> 1961.5426 | E9: =Forecast!E4*Assumptions!D8 -> 2049.8121 | F9: =Forecast!F4*Assumptions!E8 -> 2131.8045 | G9: =Forecast!G4*Assumptions!F8 -> 2217.0767
A10: Inventory | B10: ='Historical Financials'!E46 -> 5743.69 | C10: =Forecast!C4*Assumptions!B9 -> 3362.6445 | D10: =Forecast!D4*Assumptions!C9 -> 3530.7768 | E10: =Forecast!E4*Assumptions!D9 -> 3689.6617 | F10: =Forecast!F4*Assumptions!E9 -> 3837.2482 | G10: =Forecast!G4*Assumptions!F9 -> 3990.7381
A11: Accounts Payable | B11: ='Historical Financials'!E68+'Historical Financials'!E69 -> 3863.04 | C11: =Forecast!C4*Assumptions!B10 -> 2241.763 | D11: =Forecast!D4*Assumptions!C10 -> 2353.8512 | E11: =Forecast!E4*Assumptions!D10 -> 2459.7745 | F11: =Forecast!F4*Assumptions!E10 -> 2558.1655 | G11: =Forecast!G4*Assumptions!F10 -> 2660.4921
A12: Net Working Capital | B12: =B9+B10-B11 -> 6342.45 | C12: =C9+C10-C11 -> 2989.0174 | D12: =D9+D10-D11 -> 3138.4682 | E12: =E9+E10-E11 -> 3279.6993 | F12: =F9+F10-F11 -> 3410.8873 | G12: =G9+G10-G11 -> 3547.3228
A13: Change in NWC | C13: =C12-B12 -> -3353.4326 | D13: =D12-C12 -> 149.45087 | E13: =E12-D12 -> 141.23107 | F13: =F12-E12 -> 131.18797 | G13: =G12-F12 -> 136.43549
A14: FCFF | C14: =C6+C7-C8-C13 -> 8070.4757 | D14: =D6+D7-D8-D13 -> 4950.56 | E14: =E6+E7-E8-E13 -> 5342.0162 | F14: =F6+F7-F8-F13 -> 5571.3892 | G14: =G6+G7-G8-G13 -> 5794.2447
A15: Discount Period | C15: =1 -> 1 | D15: =C15+1 -> 2 | E15: =D15+1 -> 3 | F15: =E15+1 -> 4 | G15: =F15+1 -> 5
A16: Discount Factor | C16: =1/(1+WACC!$B$16)^C15 -> 0.89417858 | D16: =1/(1+WACC!$B$16)^D15 -> 0.79955534 | E16: =1/(1+WACC!$B$16)^E15 -> 0.71494526 | F16: =1/(1+WACC!$B$16)^F15 -> 0.63928873 | G16: =1/(1+WACC!$B$16)^G15 -> 0.57163829
A17: PV of FCFF | C17: =C14*C16 -> 7216.4465 | D17: =D14*D16 -> 3958.2467 | E17: =E14*E16 -> 3819.2491 | F17: =F14*F16 -> 3561.7263 | G17: =G14*G16 -> 3312.2122
A19: Terminal Value | B19: =G14*(1+Assumptions!B20)/(WACC!B16-Assumptions!B20) -> 89018.531
A20: PV of Terminal Value | B20: =B19*G16 -> 50886.401
A21: Enterprise Value | B21: =SUM(C17:G17)+B20 -> 72754.282
A22: Less: Debt | B22: =WACC!B12 -> 2293.26
A23: Add: Cash | B23: ='Historical Financials'!E49 -> 672.83
A24: Equity Value | B24: =B21-B22+B23 -> 71133.852
A25: Shares Outstanding | B25: ='Historical Financials'!E55 -> 95.92
A26: Intrinsic Value Per Share | B26: =B24/B25 -> 741.59562

Sheet Comparable Companies
A1: COMPARABLE COMPANIES ANALYSIS
A3: Company | B3: Market Cap | C3: Enterprise Value | D3: Revenue | E3: EBITDA | F3: PAT | G3: P/E | H3: EV/EBITDA | I3: EV/Sales
A4: Asian Paints | B4: =WACC!B11 -> 230476 | C4: =B4+WACC!B12-'Historical Financials'!E49 -> 232096.43 | D4: ='Historical Financials'!E9 -> 35583.54 | E4: ='Historical Financials'!E18 -> 7419.72 | F4: ='Historical Financials'!E27 -> 4394.69 | G4: =B4/F4 -> 52.4442 | H4: =C4/E4 -> 31.281023 | I4: =C4/D4 -> 6.5225784
A5: Berger Paints | B5: 52114.5 | C5: 54358 | D5: 11880.3 | E5: 1833.3 | F5: 1128 | G5: =B5/F5 -> 46.200798 | H5: =C5/E5 -> 29.650357 | I5: =C5/D5 -> 4.5754737
A6: Kansai Nerolac | B6: 15281.9 | C6: 12974.9 | D6: 8051.91 | E6: 974.6 | F6: 575.84 | G6: =B6/F6 -> 26.538448 | H6: =C6/E6 -> 13.313052 | I6: =C6/D6 -> 1.6114065
A7: Indigo Paints | B7: 5157 | C7: 4846 | D7: 1405.02 | E7: 254.77 | F7: 147.61 | G7: =B7/F7 -> 34.936657 | H7: =C7/E7 -> 19.021078 | I7: =C7/D7 -> 3.4490612
A10: PEER MULTIPLE SUMMARY
A12: Metric | B12: Asian Paints | C12: Berger Paints | D12: Kansai Nerolac | E12: Indigo Paints | F12: Peer Median
A13: P/E | B13: =G4 -> 52.4442 | C13: =G5 -> 46.200798 | D13: =G6 -> 26.538448 | E13: =G7 -> 34.936657 | F13: =MEDIAN(C13:E13) -> 34.936657
A14: EV/EBITDA | B14: =H4 -> 31.281023 | C14: =H5 -> 29.650357 | D14: =H6 -> 13.313052 | E14: =H7 -> 19.021078 | F14: =MEDIAN(C14:E14) -> 19.021078
A15: EV/Sales | B15: =I4 -> 6.5225784 | C15: =I5 -> 4.5754737 | D15: =I6 -> 1.6114065 | E15: =I7 -> 3.4490612 | F15: =MEDIAN(C15:E15) -> 3.4490612
A18: IMPLIED VALUATION — ASIAN PAINTS
A20: Method | B20: Peer Median | C20: Asian Paints Metric | D20: Implied Enterprise/Equity Value | E20: Implied Value/Share
A21: P/E | B21: =F13 -> 34.936657 | C21: =F4 -> 4394.69 | D21: =B21*C21 -> 153535.78 | E21: =D21/95.92 -> 1600.6649
A22: EV/EBITDA | B22: =F14 -> 19.021078 | C22: =E4 -> 7419.72 | D22: =B22*C22 -> 141131.07 | E22: =(D22-WACC!B12+'Historical Financials'!E49)/95.92 -> 1454.4479
A23: EV/Sales | B23: =F15 -> 3.4490612 | C23: =D4 -> 35583.54 | D23: =B23*C23 -> 122729.81 | E23: =(D23-WACC!B12+'Historical Financials'!E49)/95.92 -> 1262.6082

Sheet Sensitivity Analysis
A1: DCF SENSITIVITY ANALYSIS
A3: WACC / Terminal Growth | B3: 0.04 | C3: 0.045 | D3: 0.05 | E3: 0.055 | F3: 0.06
A4: 0.1083 | B4: =( SUMPRODUCT('DCF Valuation'!$C$14:$G$14,1/(1+$A4)^'DCF Valuation'!$C$15:$G$15) + ('DCF Valuation'!$G$14*(1+B$3))/($A4-B$3)/(1+$A4)^'DCF Valuation'!$G$15 -WACC!$B$12 +'Historical Financials'!$E$49 )/'DCF Valuation'!$B$25 -> 766.63512 | C4: =( SUMPRODUCT('DCF Valuation'!$C$14:$G$14,1/(1+$A4)^'DCF Valuation'!$C$15:$G$15) + ('DCF Valuation'!$G$14*(1+C$3))/($A4-C$3)/(1+$A4)^'DCF Valuation'!$G$15 -WACC!$B$12 +'Historical Financials'!$E$49 )/'DCF Valuation'!$B$25 -> 812.93757 | D4: =( SUMPRODUCT('DCF Valuation'!$C$14:$G$14,1/(1+$A4)^'DCF Valuation'!$C$15:$G$15) + ('DCF Valuation'!$G$14*(1+D$3))/($A4-D$3)/(1+$A4)^'DCF Valuation'!$G$15 -WACC!$B$12 +'Historical Financials'!$E$49 )/'DCF Valuation'!$B$25 -> 867.18211 | E4: =( SUMPRODUCT('DCF Valuation'!$C$14:$G$14,1/(1+$A4)^'DCF Valuation'!$C$15:$G$15) + ('DCF Valuation'!$G$14*(1+E$3))/($A4-E$3)/(1+$A4)^'DCF Valuation'!$G$15 -WACC!$B$12 +'Historical Financials'!$E$49 )/'DCF Valuation'!$B$25 -> 931.60387 | F4: =( SUMPRODUCT('DCF Valuation'!$C$14:$G$14,1/(1+$A4)^'DCF Valuation'!$C$15:$G$15) + ('DCF Valuation'!$G$14*(1+F$3))/($A4-F$3)/(1+$A4)^'DCF Valuation'!$G$15 -WACC!$B$12 +'Historical Financials'!$E$49 )/'DCF Valuation'!$B$25 -> 1009.3635
A5: 0.1133 | B5: =( SUMPRODUCT('DCF Valuation'!$C$14:$G$14,1/(1+$A5)^'DCF Valuation'!$C$15:$G$15) + ('DCF Valuation'!$G$14*(1+B$3))/($A5-B$3)/(1+$A5)^'DCF Valuation'!$G$15 -WACC!$B$12 +'Historical Financials'!$E$49 )/'DCF Valuation'!$B$25 -> 714.94992 | C5: =( SUMPRODUCT('DCF Valuation'!$C$14:$G$14,1/(1+$A5)^'DCF Valuation'!$C$15:$G$15) + ('DCF Valuation'!$G$14*(1+C$3))/($A5-C$3)/(1+$A5)^'DCF Valuation'!$G$15 -WACC!$B$12 +'Historical Financials'!$E$49 )/'DCF Valuation'!$B$25 -> 754.22202 | D5: =( SUMPRODUCT('DCF Valuation'!$C$14:$G$14,1/(1+$A5)^'DCF Valuation'!$C$15:$G$15) + ('DCF Valuation'!$G$14*(1+D$3))/($A5-D$3)/(1+$A5)^'DCF Valuation'!$G$15 -WACC!$B$12 +'Historical Financials'!$E$49 )/'DCF Valuation'!$B$25 -> 799.69825 | E5: =( SUMPRODUCT('DCF Valuation'!$C$14:$G$14,1/(1+$A5)^'DCF Valuation'!$C$15:$G$15) + ('DCF Valuation'!$G$14*(1+E$3))/($A5-E$3)/(1+$A5)^'DCF Valuation'!$G$15 -WACC!$B$12 +'Historical Financials'!$E$49 )/'DCF Valuation'!$B$25 -> 852.97486 | F5: =( SUMPRODUCT('DCF Valuation'!$C$14:$G$14,1/(1+$A5)^'DCF Valuation'!$C$15:$G$15) + ('DCF Valuation'!$G$14*(1+F$3))/($A5-F$3)/(1+$A5)^'DCF Valuation'!$G$15 -WACC!$B$12 +'Historical Financials'!$E$49 )/'DCF Valuation'!$B$25 -> 916.24708
A6: 0.1183 | B6: =( SUMPRODUCT('DCF Valuation'!$C$14:$G$14,1/(1+$A6)^'DCF Valuation'!$C$15:$G$15) + ('DCF Valuation'!$G$14*(1+B$3))/($A6-B$3)/(1+$A6)^'DCF Valuation'!$G$15 -WACC!$B$12 +'Historical Financials'!$E$49 )/'DCF Valuation'!$B$25 -> 669.85191 | C6: =( SUMPRODUCT('DCF Valuation'!$C$14:$G$14,1/(1+$A6)^'DCF Valuation'!$C$15:$G$15) + ('DCF Valuation'!$G$14*(1+C$3))/($A6-C$3)/(1+$A6)^'DCF Valuation'!$G$15 -WACC!$B$12 +'Historical Financials'!$E$49 )/'DCF Valuation'!$B$25 -> 703.49986 | D6: =( SUMPRODUCT('DCF Valuation'!$C$14:$G$14,1/(1+$A6)^'DCF Valuation'!$C$15:$G$15) + ('DCF Valuation'!$G$14*(1+D$3))/($A6-D$3)/(1+$A6)^'DCF Valuation'!$G$15 -WACC!$B$12 +'Historical Financials'!$E$49 )/'DCF Valuation'!$B$25 -> 742.07431 | E6: =( SUMPRODUCT('DCF Valuation'!$C$14:$G$14,1/(1+$A6)^'DCF Valuation'!$C$15:$G$15) + ('DCF Valuation'!$G$14*(1+E$3))/($A6-E$3)/(1+$A6)^'DCF Valuation'!$G$15 -WACC!$B$12 +'Historical Financials'!$E$49 )/'DCF Valuation'!$B$25 -> 786.74266 | F6: =( SUMPRODUCT('DCF Valuation'!$C$14:$G$14,1/(1+$A6)^'DCF Valuation'!$C$15:$G$15) + ('DCF Valuation'!$G$14*(1+F$3))/($A6-F$3)/(1+$A6)^'DCF Valuation'!$G$15 -WACC!$B$12 +'Historical Financials'!$E$49 )/'DCF Valuation'!$B$25 -> 839.07283
A7: 0.1233 | B7: =( SUMPRODUCT('DCF Valuation'!$C$14:$G$14,1/(1+$A7)^'DCF Valuation'!$C$15:$G$15) + ('DCF Valuation'!$G$14*(1+B$3))/($A7-B$3)/(1+$A7)^'DCF Valuation'!$G$15 -WACC!$B$12 +'Historical Financials'!$E$49 )/'DCF Valuation'!$B$25 -> 630.15508 | C7: =( SUMPRODUCT('DCF Valuation'!$C$14:$G$14,1/(1+$A7)^'DCF Valuation'!$C$15:$G$15) + ('DCF Valuation'!$G$14*(1+C$3))/($A7-C$3)/(1+$A7)^'DCF Valuation'!$G$15 -WACC!$B$12 +'Historical Financials'!$E$49 )/'DCF Valuation'!$B$25 -> 659.24 | D7: =( SUMPRODUCT('DCF Valuation'!$C$14:$G$14,1/(1+$A7)^'DCF Valuation'!$C$15:$G$15) + ('DCF Valuation'!$G$14*(1+D$3))/($A7-D$3)/(1+$A7)^'DCF Valuation'!$G$15 -WACC!$B$12 +'Historical Financials'!$E$49 )/'DCF Valuation'!$B$25 -> 692.29285 | E7: =( SUMPRODUCT('DCF Valuation'!$C$14:$G$14,1/(1+$A7)^'DCF Valuation'!$C$15:$G$15) + ('DCF Valuation'!$G$14*(1+E$3))/($A7-E$3)/(1+$A7)^'DCF Valuation'!$G$15 -WACC!$B$12 +'Historical Financials'!$E$49 )/'DCF Valuation'!$B$25 -> 730.18506 | F7: =( SUMPRODUCT('DCF Valuation'!$C$14:$G$14,1/(1+$A7)^'DCF Valuation'!$C$15:$G$15) + ('DCF Valuation'!$G$14*(1+F$3))/($A7-F$3)/(1+$A7)^'DCF Valuation'!$G$15 -WACC!$B$12 +'Historical Financials'!$E$49 )/'DCF Valuation'!$B$25 -> 774.0634
A8: 0.1283 | B8: =( SUMPRODUCT('DCF Valuation'!$C$14:$G$14,1/(1+$A8)^'DCF Valuation'!$C$15:$G$15) + ('DCF Valuation'!$G$14*(1+B$3))/($A8-B$3)/(1+$A8)^'DCF Valuation'!$G$15 -WACC!$B$12 +'Historical Financials'!$E$49 )/'DCF Valuation'!$B$25 -> 594.94205 | C8: =( SUMPRODUCT('DCF Valuation'!$C$14:$G$14,1/(1+$A8)^'DCF Valuation'!$C$15:$G$15) + ('DCF Valuation'!$G$14*(1+C$3))/($A8-C$3)/(1+$A8)^'DCF Valuation'!$G$15 -WACC!$B$12 +'Historical Financials'!$E$49 )/'DCF Valuation'!$B$25 -> 620.27896 | D8: =( SUMPRODUCT('DCF Valuation'!$C$14:$G$14,1/(1+$A8)^'DCF Valuation'!$C$15:$G$15) + ('DCF Valuation'!$G$14*(1+D$3))/($A8-D$3)/(1+$A8)^'DCF Valuation'!$G$15 -WACC!$B$12 +'Historical Financials'!$E$49 )/'DCF Valuation'!$B$25 -> 648.85174 | E8: =( SUMPRODUCT('DCF Valuation'!$C$14:$G$14,1/(1+$A8)^'DCF Valuation'!$C$15:$G$15) + ('DCF Valuation'!$G$14*(1+E$3))/($A8-E$3)/(1+$A8)^'DCF Valuation'!$G$15 -WACC!$B$12 +'Historical Financials'!$E$49 )/'DCF Valuation'!$B$25 -> 681.32259 | F8: =( SUMPRODUCT('DCF Valuation'!$C$14:$G$14,1/(1+$A8)^'DCF Valuation'!$C$15:$G$15) + ('DCF Valuation'!$G$14*(1+F$3))/($A8-F$3)/(1+$A8)^'DCF Valuation'!$G$15 -WACC!$B$12 +'Historical Financials'!$E$49 )/'DCF Valuation'!$B$25 -> 718.54758

Sheet Valuation Summary
A1: VALUATION SUMMARY
A3: Metric | B3: Value
A4: Current Market Price | B4: 1620
A5: DCF Intrinsic Value | B5: ='DCF Valuation'!B26 -> 741.59562
A6: DCF Upside / (Downside) | B6: =B5/B4-1 -> -0.54222493
A7: P/E Implied Value | B7: ='Comparable Companies'!E21 -> 1600.6649
A8: EV/EBITDA Implied Value | B8: ='Comparable Companies'!E22 -> 1454.4479
A9: EV/Sales Implied Value | B9: ='Comparable Companies'!E23 -> 1262.6082
A10: Average Comparable Value | B10: =AVERAGE(B7:B9) -> 1439.2403
A11: WACC | B11: =WACC!B16 -> 0.11834484
A12: Terminal Growth | B12: =Assumptions!B20 -> 0.05
A15: VALUATION METHOD COMPARISON
A17: Method | B17: Implied Value/Share | C17: Premium / (Discount) to Market
A18: DCF | B18: =B5 -> 741.59562 | C18: =B18/$B$4-1 -> -0.54222493
A19: P/E | B19: =B7 -> 1600.6649 | C19: =B19/$B$4-1 -> -0.011935236
A20: EV/EBITDA | B20: =B8 -> 1454.4479 | C20: =B20/$B$4-1 -> -0.10219266
A21: EV/Sales | B21: =B9 -> 1262.6082 | C21: =B21/$B$4-1 -> -0.22061223
A24: KEY VALUATION OUTPUT
A26: DCF Intrinsic Value / Share | B26: =B5 -> 741.59562
A27: Average Comparable Value / Share | B27: =B10 -> 1439.2403
A28: Current Market Price | B28: =B4 -> 1620

Sheet Dashboard
A1: ASIAN PAINTS LTD.
A3: EQUITY VALUATION & FINANCIAL MODEL | FY23A–FY31E
A5: CURRENT MARKET PRICE | D5: DCF INTRINSIC VALUE | G5: AVERAGE COMPARABLE VALUE | J5: DCF UPSIDE / (DOWNSIDE)
A6: ='Valuation Summary'!B4 -> 1620 | D6: ='Valuation Summary'!B5 -> 741.59562 | G6: ='Valuation Summary'!B10 -> 1439.2403 | J6: ='Valuation Summary'!B6 -> -0.54222493
A10: VALUATION COMPARISON | G10: FY26A FINANCIAL SNAPSHOT
A11: Method | B11: Implied Value/Share | C11: Premium / (Discount) | G11: Revenue | H11: =Forecast!B4 -> 35583.54
A12: DCF | B12: ='Valuation Summary'!B18 -> 741.59562 | C12: ='Valuation Summary'!C18 -> -0.54222493 | G12: EBITDA | H12: =Forecast!B6 -> 7419.72
A13: P/E | B13: ='Valuation Summary'!B19 -> 1600.6649 | C13: ='Valuation Summary'!C19 -> -0.011935236 | G13: PAT | H13: ='Historical Financials'!E27 -> 4394.69
A14: EV/EBITDA | B14: ='Valuation Summary'!B20 -> 1454.4479 | C14: ='Valuation Summary'!C20 -> -0.10219266 | G14: EBITDA Margin | H14: ='Financial Ratios'!D5 -> 0.20851551
A15: EV/Sales | B15: ='Valuation Summary'!B21 -> 1262.6082 | C15: ='Valuation Summary'!C21 -> -0.22061223 | G15: ROE | H15: ='Financial Ratios'!D8 -> 0.20890274
A16: Market Price | B16: ='Valuation Summary'!B4 -> 1620 | C16: =0 -> 0
A18: HISTORICAL PROFITABILITY | G18: FORECAST SNAPSHOT
A19: Metric | B19: FY23 | C19: FY24 | D19: FY25 | E19: FY26 | G19: Metric | H19: FY26A | I19: FY27E | J19: FY28E | K19: FY29E | L19: FY30E | M19: FY31E
A20: EBITDA Margin | B20: ='Historical Financials'!B18/'Historical Financials'!B9 -> 0.19271069 | C20: ='Historical Financials'!C18/'Historical Financials'!C9 -> 0.23307516 | D20: ='Historical Financials'!D18/'Historical Financials'!D9 -> 0.19403332 | E20: ='Historical Financials'!E18/'Historical Financials'!E9 -> 0.20851551 | G20: Revenue | H20: =Forecast!B4 -> 35583.54 | I20: =Forecast!C4 -> 37362.717 | J20: =Forecast!D4 -> 39230.853 | K20: =Forecast!E4 -> 40996.241 | L20: =Forecast!F4 -> 42636.091 | M20: =Forecast!G4 -> 44341.535
A21: Net Profit Margin | B21: ='Historical Financials'!B27/'Historical Financials'!B9 -> 0.121644 | C21: ='Historical Financials'!C27/'Historical Financials'!C9 -> 0.15657789 | D21: ='Historical Financials'!D27/'Historical Financials'!D9 -> 0.10941283 | E21: ='Historical Financials'!E27/'Historical Financials'!E9 -> 0.12350345 | G21: EBITDA | H21: =Forecast!B6 -> 7419.72 | I21: =Forecast!C6 -> 7846.1706 | J21: =Forecast!D6 -> 8434.6334 | K21: =Forecast!E6 -> 9019.1731 | L21: =Forecast!F6 -> 9379.94 | M21: =Forecast!G6 -> 9755.1376
A37: KEY VALUATION ASSUMPTIONS | G37: DCF SENSITIVITY — VALUE / SHARE
A38: WACC | B38: =WACC!B16 -> 0.11834484 | G38: WACC / Growth | H38: ='Sensitivity Analysis'!B3 -> 0.04 | I38: ='Sensitivity Analysis'!C3 -> 0.045 | J38: ='Sensitivity Analysis'!D3 -> 0.05 | K38: ='Sensitivity Analysis'!E3 -> 0.055 | L38: ='Sensitivity Analysis'!F3 -> 0.06
A39: Terminal Growth | B39: =Assumptions!B20 -> 0.05 | G39: ='Sensitivity Analysis'!A4 -> 0.1083 | H39: ='Sensitivity Analysis'!B4 -> 766.63512 | I39: ='Sensitivity Analysis'!C4 -> 812.93757 | J39: ='Sensitivity Analysis'!D4 -> 867.18211 | K39: ='Sensitivity Analysis'!E4 -> 931.60387 | L39: ='Sensitivity Analysis'!F4 -> 1009.3635
A40: Risk-Free Rate | B40: =WACC!B4 -> 0.065 | G40: ='Sensitivity Analysis'!A5 -> 0.1133 | H40: ='Sensitivity Analysis'!B5 -> 714.94992 | I40: ='Sensitivity Analysis'!C5 -> 754.22202 | J40: ='Sensitivity Analysis'!D5 -> 799.69825 | K40: ='Sensitivity Analysis'!E5 -> 852.97486 | L40: ='Sensitivity Analysis'!F5 -> 916.24708
A41: Equity Risk Premium | B41: =WACC!B5 -> 0.06 | G41: ='Sensitivity Analysis'!A6 -> 0.1183 | H41: ='Sensitivity Analysis'!B6 -> 669.85191 | I41: ='Sensitivity Analysis'!C6 -> 703.49986 | J41: ='Sensitivity Analysis'!D6 -> 742.07431 | K41: ='Sensitivity Analysis'!E6 -> 786.74266 | L41: ='Sensitivity Analysis'!F6 -> 839.07283
A42: Beta | B42: =WACC!B6 -> 0.9 | G42: ='Sensitivity Analysis'!A7 -> 0.1233 | H42: ='Sensitivity Analysis'!B7 -> 630.15508 | I42: ='Sensitivity Analysis'!C7 -> 659.24 | J42: ='Sensitivity Analysis'!D7 -> 692.29285 | K42: ='Sensitivity Analysis'!E7 -> 730.18506 | L42: ='Sensitivity Analysis'!F7 -> 774.0634
A43: Pre-Tax Cost of Debt | B43: =WACC!B8 -> 0.07 | G43: ='Sensitivity Analysis'!A8 -> 0.1283 | H43: ='Sensitivity Analysis'!B8 -> 594.94205 | I43: ='Sensitivity Analysis'!C8 -> 620.27896 | J43: ='Sensitivity Analysis'!D8 -> 648.85174 | K43: ='Sensitivity Analysis'!E8 -> 681.32259 | L43: ='Sensitivity Analysis'!F8 -> 718.54758
A45: Dashboard note: FY26A is actual; FY27E–FY31E are model forecasts. Valuation outputs are sourced from the underlying DCF and comparable-company analysis. | H45: BASE CASE DCF
H46: ₹742.07
